<?xml version="1.0"?>
<robot name="l2_robot"
    xmlns:xacro="http://ros.org/wiki/xacro">

    <!-- Define arguments -->
    <xacro:arg name="prefix" default=""/>

    <!-- Define robot constants -->
    <xacro:property name="base_width" value="0.35"/>
    <xacro:property name="base_length" value="0.35"/>
    <xacro:property name="base_height" value="0.35"/>
    <xacro:property name="base_mass" value="1.0"/>

    <xacro:property name="thigh_length" value="0.35"/>
    <xacro:property name="thigh_radius" value="0.05"/>
    <xacro:property name="thigh_mass" value="1.0"/>

    <xacro:property name="leg_length" value="0.35"/>
    <xacro:property name="leg_radius" value="0.05"/>
    <xacro:property name="leg_mass" value="1.0"/>

    <xacro:property name="foot_length" value="0.25"/>
    <xacro:property name="foot_width" value="0.25"/>
    <xacro:property name="foot_height" value="0.05"/>
    <xacro:property name="foot_mass" value="0.5"/>

    <xacro:property name="lidar_radius" value="0.05"/>
    <xacro:property name="lidar_length" value="0.05"/>
    <xacro:property name="lidar_mass" value="0.05"/>

    <!-- Define some commonly used intertial properties  -->
    <xacro:macro name="box_inertia" params="m w h d">
        <inertial>
        <origin xyz="0 0 0" rpy="${pi/2} 0 ${pi/2}"/>
        <mass value="${m}"/>
        <inertia ixx="${(m/12) * (h*h + d*d)}" ixy="0.0" ixz="0.0" iyy="${(m/12) * (w*w + d*d)}" iyz="0.0" izz="${(m/12) * (w*w + h*h)}"/>
        </inertial>
    </xacro:macro>

    <xacro:macro name="cylinder_inertia" params="m r h">
        <inertial>
        <origin xyz="0 0 0" rpy="${pi/2} 0 0" />
        <mass value="${m}"/>
        <inertia ixx="${(m/12) * (3*r*r + h*h)}" ixy = "0" ixz = "0" iyy="${(m/12) * (3*r*r + h*h)}" iyz = "0" izz="${(m/2) * (r*r)}"/>
        </inertial>
    </xacro:macro>

    <!-- Robot Base -->
    <link name="base_link">
        <visual>
            <geometry>
                <box size="${base_length} ${base_width} ${base_height}"/>
            </geometry>
            <material name="Cyan">
                <color rgba="0 1.0 1.0 1.0"/>
            </material>
        </visual>

        <collision>
            <geometry>
                <box size="${base_length} ${base_width} ${base_height}"/>
            </geometry>
        </collision>

        <xacro:box_inertia m="${base_mass}" w="${base_length}" h="${base_width}" d="${base_height}"/>
    </link>

    <!-- Thigh Link -->
    <xacro:macro name="thigh" params="prefix y_reflect">
        <link name="${prefix}_thigh_link">
            <visual>
                <origin xyz="0 0 ${-thigh_length/2}" rpy="0 0 0"/>
                <geometry>
                    <cylinder radius="${thigh_radius}" length="${thigh_length}"/>
                </geometry>
                <material name="Gray">
                    <color rgba="0.5 0.5 0.5 1.0"/>
                </material>
            </visual>

            <collision>
                <origin xyz="0 0 ${thigh_length/2}" rpy="0 0 0"/>
                <geometry>
                    <cylinder radius="${thigh_radius}" length="${thigh_length}"/>
                </geometry>
            </collision>

            <xacro:cylinder_inertia m="${thigh_mass}" r="${thigh_radius}" h="${thigh_length}"/>
        </link>

        <joint name="${prefix}_hip_joint" type="revolute">
            <parent link="base_link"/>
            <child link="${prefix}_thigh_link"/>
            <origin xyz="${y_reflect*(base_length/2+thigh_radius+0.01)} 0 ${-base_height/2 + 0.1}" rpy="0 0 0"/>
            <axis xyz="1 0 0"/>
            <limit lower="-1.57" upper="1.57" effort="10.0" velocity="1.0"/>
        </joint>
    </xacro:macro>

    <xacro:thigh prefix="left" y_reflect="-1"/>
    <xacro:thigh prefix="right" y_reflect="1"/>

    <!-- Leg Link -->
    <xacro:macro name="leg" params="prefix">
        <link name="${prefix}_leg_link">
            <visual>
                <origin xyz="0 0 ${-leg_length/2}" rpy="0 0 0"/>
                <geometry>
                    <cylinder radius="${leg_radius}" length="${leg_length}"/>
                </geometry>
                <material name="Gray">
                    <color rgba="0.5 0.5 0.5 1.0"/>
                </material>
            </visual>

            <collision>
                <origin xyz="0 0 ${leg_length/2}" rpy="0 0 0"/>
                <geometry>
                    <cylinder radius="${leg_radius}" length="${leg_length}"/>
                </geometry>
            </collision>

            <xacro:cylinder_inertia m="${leg_mass}" r="${leg_radius}" h="${leg_length}"/>
        </link>

        <joint name="${prefix}_knuckle_joint" type="revolute">
            <parent link="${prefix}_thigh_link"/>
            <child link="${prefix}_leg_link"/>
            <origin xyz="0 0 ${-thigh_length - 0.015}" rpy="0 0 0"/>
            <axis xyz="1 0 0"/>
            <limit lower="-1.57" upper="0.0" effort="10.0" velocity="1.0"/>
        </joint>
    </xacro:macro>

    <xacro:leg prefix="left"/>
    <xacro:leg prefix="right"/>

    <!-- Foot Link -->
    <xacro:macro name="foot" params="prefix y_reflect">
        <link name="${prefix}_foot_link">
            <visual>
                <origin xyz="0 ${foot_width/2 - leg_radius - 0.02} ${-foot_height/2}" rpy="0 0 0"/>
                <geometry>
                    <box size="${foot_length} ${foot_width} ${foot_height}"/>
                </geometry>
                <material name="Gray">
                    <color rgba="0.5 0.5 0.5 1.0"/>
                </material>
            </visual>

            <collision>
                <origin xyz="0 ${foot_width/2 - leg_radius - 0.02} ${-foot_height/2}" rpy="0 0 0"/>
                <geometry>
                    <box size="${foot_length} ${foot_width} ${foot_height}"/>
                </geometry>
            </collision>

            <xacro:box_inertia m="${foot_mass}" w="${foot_length}" h="${foot_width}" d="${foot_height}"/>
        </link>

        <joint name="${prefix}_ankle_joint" type="revolute">
            <parent link="${prefix}_leg_link"/>
            <child link="${prefix}_foot_link"/>
            <origin xyz="0 0 ${-leg_length - foot_height/2}" rpy="0 0 0"/>
            <axis xyz="1 0 0"/>
            <limit lower="-1.57" upper="1.57" effort="10.0" velocity="1.0"/>
        </joint>
    </xacro:macro>

    <xacro:foot prefix="left" y_reflect="-1"/>
    <xacro:foot prefix="right" y_reflect="1"/>

    <!-- Lidar Link -->
    <link name="lidar_link">
        <visual>
            <origin xyz="0 0 0" rpy="0 0 0"/>
            <geometry>
                <cylinder radius="${lidar_radius}" length="${lidar_length}"/>
            </geometry>
            <material name="Black">
                <color rgba="0 0 0 1.0"/>
            </material>
        </visual>

        <collision>
            <origin xyz="0 0 0" rpy="0 0 0"/>
            <geometry>
                <cylinder radius="${lidar_radius}" length="${lidar_length}"/>
            </geometry>
        </collision>

        <xacro:cylinder_inertia m="${lidar_mass}" r="${lidar_radius}" h="${lidar_length}"/>
    </link>
    <joint name="lidar_joint" type="fixed">
        <parent link="base_link"/>
        <child link="lidar_link"/>
        <origin xyz="0 0 ${base_height/2 + lidar_length/2}" rpy="0 0 0"/>
    </joint>

</robot>
