<?xml version="1.0" ?>
<!-- =================================================================================== -->
<!-- |    This document was autogenerated by xacro from l2.urdf                        | -->
<!-- |    EDITING THIS FILE BY HAND IS NOT RECOMMENDED                                 | -->
<!-- =================================================================================== -->
<robot name="l2_robot">
  <!-- Robot Base -->
  <link name="base_link">
    <visual>
      <geometry>
        <box size="0.35 0.35 0.35"/>
      </geometry>
      <material name="Cyan">
        <color rgba="0 1.0 1.0 1.0"/>
      </material>
    </visual>
    <collision>
      <geometry>
        <box size="0.35 0.35 0.35"/>
      </geometry>
    </collision>
    <inertial>
      <origin rpy="1.5707963267948966 0 1.5707963267948966" xyz="0 0 0"/>
      <mass value="1.0"/>
      <inertia ixx="0.020416666666666663" ixy="0.0" ixz="0.0" iyy="0.020416666666666663" iyz="0.0" izz="0.020416666666666663"/>
    </inertial>
  </link>
  <link name="left_thigh_link">
    <visual>
      <origin rpy="0 0 0" xyz="0 0 -0.175"/>
      <geometry>
        <cylinder length="0.35" radius="0.05"/>
      </geometry>
      <material name="Gray">
        <color rgba="0.5 0.5 0.5 1.0"/>
      </material>
    </visual>
    <collision>
      <origin rpy="0 0 0" xyz="0 0 0.175"/>
      <geometry>
        <cylinder length="0.35" radius="0.05"/>
      </geometry>
    </collision>
    <inertial>
      <origin rpy="1.5707963267948966 0 0" xyz="0 0 0"/>
      <mass value="1.0"/>
      <inertia ixx="0.01083333333333333" ixy="0" ixz="0" iyy="0.01083333333333333" iyz="0" izz="0.0012500000000000002"/>
    </inertial>
  </link>
  <joint name="left_hip_joint" type="revolute">
    <parent link="base_link"/>
    <child link="left_thigh_link"/>
    <origin rpy="0 0 0" xyz="-0.235 0 -0.07499999999999998"/>
    <axis xyz="1 0 0"/>
    <limit effort="10.0" lower="-1.57" upper="1.57" velocity="1.0"/>
  </joint>
  <link name="right_thigh_link">
    <visual>
      <origin rpy="0 0 0" xyz="0 0 -0.175"/>
      <geometry>
        <cylinder length="0.35" radius="0.05"/>
      </geometry>
      <material name="Gray">
        <color rgba="0.5 0.5 0.5 1.0"/>
      </material>
    </visual>
    <collision>
      <origin rpy="0 0 0" xyz="0 0 0.175"/>
      <geometry>
        <cylinder length="0.35" radius="0.05"/>
      </geometry>
    </collision>
    <inertial>
      <origin rpy="1.5707963267948966 0 0" xyz="0 0 0"/>
      <mass value="1.0"/>
      <inertia ixx="0.01083333333333333" ixy="0" ixz="0" iyy="0.01083333333333333" iyz="0" izz="0.0012500000000000002"/>
    </inertial>
  </link>
  <joint name="right_hip_joint" type="revolute">
    <parent link="base_link"/>
    <child link="right_thigh_link"/>
    <origin rpy="0 0 0" xyz="0.235 0 -0.07499999999999998"/>
    <axis xyz="1 0 0"/>
    <limit effort="10.0" lower="-1.57" upper="1.57" velocity="1.0"/>
  </joint>
  <link name="left_leg_link">
    <visual>
      <origin rpy="0 0 0" xyz="0 0 -0.175"/>
      <geometry>
        <cylinder length="0.35" radius="0.05"/>
      </geometry>
      <material name="Gray">
        <color rgba="0.5 0.5 0.5 1.0"/>
      </material>
    </visual>
    <collision>
      <origin rpy="0 0 0" xyz="0 0 0.175"/>
      <geometry>
        <cylinder length="0.35" radius="0.05"/>
      </geometry>
    </collision>
    <inertial>
      <origin rpy="1.5707963267948966 0 0" xyz="0 0 0"/>
      <mass value="1.0"/>
      <inertia ixx="0.01083333333333333" ixy="0" ixz="0" iyy="0.01083333333333333" iyz="0" izz="0.0012500000000000002"/>
    </inertial>
  </link>
  <joint name="left_knuckle_joint" type="revolute">
    <parent link="left_thigh_link"/>
    <child link="left_leg_link"/>
    <origin rpy="0 0 0" xyz="0 0 -0.365"/>
    <axis xyz="1 0 0"/>
    <limit effort="10.0" lower="-1.57" upper="0.0" velocity="1.0"/>
  </joint>
  <link name="right_leg_link">
    <visual>
      <origin rpy="0 0 0" xyz="0 0 -0.175"/>
      <geometry>
        <cylinder length="0.35" radius="0.05"/>
      </geometry>
      <material name="Gray">
        <color rgba="0.5 0.5 0.5 1.0"/>
      </material>
    </visual>
    <collision>
      <origin rpy="0 0 0" xyz="0 0 0.175"/>
      <geometry>
        <cylinder length="0.35" radius="0.05"/>
      </geometry>
    </collision>
    <inertial>
      <origin rpy="1.5707963267948966 0 0" xyz="0 0 0"/>
      <mass value="1.0"/>
      <inertia ixx="0.01083333333333333" ixy="0" ixz="0" iyy="0.01083333333333333" iyz="0" izz="0.0012500000000000002"/>
    </inertial>
  </link>
  <joint name="right_knuckle_joint" type="revolute">
    <parent link="right_thigh_link"/>
    <child link="right_leg_link"/>
    <origin rpy="0 0 0" xyz="0 0 -0.365"/>
    <axis xyz="1 0 0"/>
    <limit effort="10.0" lower="-1.57" upper="0.0" velocity="1.0"/>
  </joint>
  <link name="left_foot_link">
    <visual>
      <origin rpy="0 0 0" xyz="0 0.05499999999999999 -0.025"/>
      <geometry>
        <box size="0.25 0.25 0.05"/>
      </geometry>
      <material name="Gray">
        <color rgba="0.5 0.5 0.5 1.0"/>
      </material>
    </visual>
    <collision>
      <origin rpy="0 0 0" xyz="0 0.05499999999999999 -0.025"/>
      <geometry>
        <box size="0.25 0.25 0.05"/>
      </geometry>
    </collision>
    <inertial>
      <origin rpy="1.5707963267948966 0 1.5707963267948966" xyz="0 0 0"/>
      <mass value="0.5"/>
      <inertia ixx="0.0027083333333333334" ixy="0.0" ixz="0.0" iyy="0.0027083333333333334" iyz="0.0" izz="0.005208333333333333"/>
    </inertial>
  </link>
  <joint name="left_ankle_joint" type="revolute">
    <parent link="left_leg_link"/>
    <child link="left_foot_link"/>
    <origin rpy="0 0 0" xyz="0 0 -0.375"/>
    <axis xyz="1 0 0"/>
    <limit effort="10.0" lower="-1.57" upper="1.57" velocity="1.0"/>
  </joint>
  <link name="right_foot_link">
    <visual>
      <origin rpy="0 0 0" xyz="0 0.05499999999999999 -0.025"/>
      <geometry>
        <box size="0.25 0.25 0.05"/>
      </geometry>
      <material name="Gray">
        <color rgba="0.5 0.5 0.5 1.0"/>
      </material>
    </visual>
    <collision>
      <origin rpy="0 0 0" xyz="0 0.05499999999999999 -0.025"/>
      <geometry>
        <box size="0.25 0.25 0.05"/>
      </geometry>
    </collision>
    <inertial>
      <origin rpy="1.5707963267948966 0 1.5707963267948966" xyz="0 0 0"/>
      <mass value="0.5"/>
      <inertia ixx="0.0027083333333333334" ixy="0.0" ixz="0.0" iyy="0.0027083333333333334" iyz="0.0" izz="0.005208333333333333"/>
    </inertial>
  </link>
  <joint name="right_ankle_joint" type="revolute">
    <parent link="right_leg_link"/>
    <child link="right_foot_link"/>
    <origin rpy="0 0 0" xyz="0 0 -0.375"/>
    <axis xyz="1 0 0"/>
    <limit effort="10.0" lower="-1.57" upper="1.57" velocity="1.0"/>
  </joint>
  <!-- Lidar Link -->
  <link name="lidar_link">
    <visual>
      <origin rpy="0 0 0" xyz="0 0 0"/>
      <geometry>
        <cylinder length="0.05" radius="0.05"/>
      </geometry>
      <material name="Black">
        <color rgba="0 0 0 1.0"/>
      </material>
    </visual>
    <collision>
      <origin rpy="0 0 0" xyz="0 0 0"/>
      <geometry>
        <cylinder length="0.05" radius="0.05"/>
      </geometry>
    </collision>
    <inertial>
      <origin rpy="1.5707963267948966 0 0" xyz="0 0 0"/>
      <mass value="0.05"/>
      <inertia ixx="4.166666666666667e-05" ixy="0" ixz="0" iyy="4.166666666666667e-05" iyz="0" izz="6.250000000000001e-05"/>
    </inertial>
  </link>
  <joint name="lidar_joint" type="fixed">
    <parent link="base_link"/>
    <child link="lidar_link"/>
    <origin rpy="0 0 0" xyz="0 0 0.19999999999999998"/>
  </joint>
</robot>
