<?xml version="1.0" ?>
<!-- =================================================================================== -->
<!-- |    This document was autogenerated by xacro from robot_ackermann.urdf           | -->
<!-- |    EDITING THIS FILE BY HAND IS NOT RECOMMENDED                                 | -->
<!-- =================================================================================== -->
<robot name="isaac_bot">
  <!-- <xacro:property name="pi" value="3.1415926535897931" /> -->
  <!-- Gap between knuckle and base_link -->
  <!-- Robot Base -->
  <link name="base_link">
    <visual>
      <geometry>
        <box size="0.42 0.31 0.18"/>
      </geometry>
      <material name="Cyan">
        <color rgba="0 1.0 1.0 1.0"/>
      </material>
    </visual>
    <collision>
      <geometry>
        <box size="0.42 0.31 0.18"/>
      </geometry>
    </collision>
    <inertial>
      <origin rpy="1.5707963267948966 0 1.5707963267948966" xyz="0 0 0"/>
      <mass value="15"/>
      <inertia ixx="0.261" ixy="0.0" ixz="0.0" iyy="0.34062499999999996" iyz="0.0" izz="0.16062500000000002"/>
    </inertial>
  </link>
  <!-- Robot Footprint -->
  <link name="base_footprint">
    <inertial>
      <origin rpy="1.5707963267948966 0 1.5707963267948966" xyz="0 0 0"/>
      <mass value="0"/>
      <inertia ixx="0.0" ixy="0.0" ixz="0.0" iyy="0.0" iyz="0.0" izz="0.0"/>
    </inertial>
  </link>
  <joint name="base_joint" type="fixed">
    <parent link="base_link"/>
    <child link="base_footprint"/>
    <origin rpy="0 0 0" xyz="0.0 0.0 -0.15000000000000002"/>
  </joint>
  <link name="knuckle_left_link">
    <visual>
      <origin rpy="1.5707963267948966 0 0" xyz="0 0.015 0"/>
      <geometry>
        <cylinder length="0.03" radius="0.02"/>
      </geometry>
      <material name="Gray">
        <color rgba="0.5 0.5 0.5 1.0"/>
      </material>
    </visual>
    <collision>
      <origin rpy="1.5707963267948966 0 0" xyz="0 0 0"/>
      <geometry>
        <cylinder length="0.03" radius="0.02"/>
      </geometry>
    </collision>
    <inertial>
      <origin rpy="1.5707963267948966 0 0" xyz="0 0 0"/>
      <mass value="0.5"/>
      <inertia ixx="8.749999999999999e-05" ixy="0" ixz="0" iyy="8.749999999999999e-05" iyz="0" izz="0.0001"/>
    </inertial>
  </link>
  <joint name="knuckle_left_joint" type="revolute">
    <parent link="base_link"/>
    <child link="knuckle_left_link"/>
    <origin rpy="0 0 0" xyz="0.12 0.165 -0.05"/>
    <axis xyz="0 0 1"/>
    <limit effort="10.0" lower="-0.5" upper="0.5" velocity="1.0"/>
  </joint>
  <link name="knuckle_right_link">
    <visual>
      <origin rpy="1.5707963267948966 0 0" xyz="0 -0.015 0"/>
      <geometry>
        <cylinder length="0.03" radius="0.02"/>
      </geometry>
      <material name="Gray">
        <color rgba="0.5 0.5 0.5 1.0"/>
      </material>
    </visual>
    <collision>
      <origin rpy="1.5707963267948966 0 0" xyz="0 0 0"/>
      <geometry>
        <cylinder length="0.03" radius="0.02"/>
      </geometry>
    </collision>
    <inertial>
      <origin rpy="1.5707963267948966 0 0" xyz="0 0 0"/>
      <mass value="0.5"/>
      <inertia ixx="8.749999999999999e-05" ixy="0" ixz="0" iyy="8.749999999999999e-05" iyz="0" izz="0.0001"/>
    </inertial>
  </link>
  <joint name="knuckle_right_joint" type="revolute">
    <parent link="base_link"/>
    <child link="knuckle_right_link"/>
    <origin rpy="0 0 0" xyz="0.12 -0.165 -0.05"/>
    <axis xyz="0 0 1"/>
    <limit effort="10.0" lower="-0.5" upper="0.5" velocity="1.0"/>
  </joint>
  <link name="back_left_wheel_link">
    <visual>
      <origin rpy="1.5707963267948966 0 0" xyz="0 0 0"/>
      <geometry>
        <cylinder length="0.04" radius="0.1"/>
      </geometry>
      <material name="Gray">
        <color rgba="0.5 0.5 0.5 1.0"/>
      </material>
    </visual>
    <collision>
      <origin rpy="1.5707963267948966 0 0" xyz="0 0 0"/>
      <geometry>
        <cylinder length="0.04" radius="0.1"/>
      </geometry>
    </collision>
    <inertial>
      <origin rpy="1.5707963267948966 0 0" xyz="0 0 0"/>
      <mass value="0.5"/>
      <inertia ixx="0.0013166666666666667" ixy="0" ixz="0" iyy="0.0013166666666666667" iyz="0" izz="0.0025000000000000005"/>
    </inertial>
  </link>
  <joint name="back_left_wheel_joint" type="continuous">
    <parent link="base_link"/>
    <child link="back_left_wheel_link"/>
    <origin rpy="0 0 0" xyz="-0.12 0.22 -0.05"/>
    <axis xyz="0 1 0"/>
  </joint>
  <link name="back_right_wheel_link">
    <visual>
      <origin rpy="1.5707963267948966 0 0" xyz="0 0 0"/>
      <geometry>
        <cylinder length="0.04" radius="0.1"/>
      </geometry>
      <material name="Gray">
        <color rgba="0.5 0.5 0.5 1.0"/>
      </material>
    </visual>
    <collision>
      <origin rpy="1.5707963267948966 0 0" xyz="0 0 0"/>
      <geometry>
        <cylinder length="0.04" radius="0.1"/>
      </geometry>
    </collision>
    <inertial>
      <origin rpy="1.5707963267948966 0 0" xyz="0 0 0"/>
      <mass value="0.5"/>
      <inertia ixx="0.0013166666666666667" ixy="0" ixz="0" iyy="0.0013166666666666667" iyz="0" izz="0.0025000000000000005"/>
    </inertial>
  </link>
  <joint name="back_right_wheel_joint" type="continuous">
    <parent link="base_link"/>
    <child link="back_right_wheel_link"/>
    <origin rpy="0 0 0" xyz="-0.12 -0.22 -0.05"/>
    <axis xyz="0 1 0"/>
  </joint>
  <link name="front_left_wheel_link">
    <visual>
      <origin rpy="1.5707963267948966 0 0" xyz="0 0 0"/>
      <geometry>
        <cylinder length="0.04" radius="0.1"/>
      </geometry>
      <material name="Gray">
        <color rgba="0.5 0.5 0.5 1.0"/>
      </material>
    </visual>
    <collision>
      <origin rpy="1.5707963267948966 0 0" xyz="0 0 0"/>
      <geometry>
        <cylinder length="0.04" radius="0.1"/>
      </geometry>
    </collision>
    <inertial>
      <origin rpy="1.5707963267948966 0 0" xyz="0 0 0"/>
      <mass value="0.5"/>
      <inertia ixx="0.0013166666666666667" ixy="0" ixz="0" iyy="0.0013166666666666667" iyz="0" izz="0.0025000000000000005"/>
    </inertial>
  </link>
  <joint name="front_left_wheel_joint" type="continuous">
    <parent link="knuckle_left_link"/>
    <child link="front_left_wheel_link"/>
    <origin rpy="0 0 0" xyz="0.0 0.055 -0.0"/>
    <axis xyz="0 1 0"/>
  </joint>
  <link name="front_right_wheel_link">
    <visual>
      <origin rpy="1.5707963267948966 0 0" xyz="0 0 0"/>
      <geometry>
        <cylinder length="0.04" radius="0.1"/>
      </geometry>
      <material name="Gray">
        <color rgba="0.5 0.5 0.5 1.0"/>
      </material>
    </visual>
    <collision>
      <origin rpy="1.5707963267948966 0 0" xyz="0 0 0"/>
      <geometry>
        <cylinder length="0.04" radius="0.1"/>
      </geometry>
    </collision>
    <inertial>
      <origin rpy="1.5707963267948966 0 0" xyz="0 0 0"/>
      <mass value="0.5"/>
      <inertia ixx="0.0013166666666666667" ixy="0" ixz="0" iyy="0.0013166666666666667" iyz="0" izz="0.0025000000000000005"/>
    </inertial>
  </link>
  <joint name="front_right_wheel_joint" type="continuous">
    <parent link="knuckle_right_link"/>
    <child link="front_right_wheel_link"/>
    <origin rpy="0 0 0" xyz="0.0 -0.055 -0.0"/>
    <axis xyz="0 1 0"/>
  </joint>
  <link name="imu_link">
    <visual>
      <geometry>
        <box size="0.1 0.1 0.1"/>
      </geometry>
    </visual>
    <collision>
      <geometry>
        <box size="0.1 0.1 0.1"/>
      </geometry>
    </collision>
    <inertial>
      <origin rpy="1.5707963267948966 0 1.5707963267948966" xyz="0 0 0"/>
      <mass value="0.1"/>
      <inertia ixx="0.0001666666666666667" ixy="0.0" ixz="0.0" iyy="0.0001666666666666667" iyz="0.0" izz="0.0001666666666666667"/>
    </inertial>
  </link>
  <joint name="imu_joint" type="fixed">
    <parent link="base_link"/>
    <child link="imu_link"/>
    <origin xyz="0 0 0.01"/>
  </joint>
  <link name="lidar_link">
    <inertial>
      <origin rpy="0 0 0" xyz="0 0 0"/>
      <mass value="0.125"/>
      <inertia ixx="0.001" ixy="0" ixz="0" iyy="0.001" iyz="0" izz="0.001"/>
    </inertial>
    <collision>
      <origin rpy="0 0 0" xyz="0 0 0"/>
      <geometry>
        <cylinder length="0.055" radius="0.0508"/>
      </geometry>
    </collision>
    <visual>
      <origin rpy="0 0 0" xyz="0 0 0"/>
      <geometry>
        <cylinder length="0.055" radius="0.0508"/>
      </geometry>
    </visual>
  </link>
  <joint name="lidar_joint" type="fixed">
    <parent link="base_link"/>
    <child link="lidar_link"/>
    <origin rpy="0 0 0" xyz="0 0 0.12"/>
  </joint>
  <link name="camera_link">
    <visual>
      <origin rpy="0 0 0" xyz="0 0 0"/>
      <geometry>
        <box size="0.015 0.130 0.022"/>
      </geometry>
    </visual>
    <collision>
      <origin rpy="0 0 0" xyz="0 0 0"/>
      <geometry>
        <box size="0.015 0.130 0.022"/>
      </geometry>
    </collision>
    <inertial>
      <origin rpy="0 0 0" xyz="0 0 0"/>
      <mass value="0.035"/>
      <inertia ixx="0.001" ixy="0" ixz="0" iyy="0.001" iyz="0" izz="0.001"/>
    </inertial>
  </link>
  <joint name="camera_joint" type="fixed">
    <parent link="base_link"/>
    <child link="camera_link"/>
    <origin rpy="0 0 0" xyz="0.215 0 0.05"/>
  </joint>
  <link name="camera_frame"/>
  <joint name="camera_depth_joint" type="fixed">
    <origin rpy="-1.5707963267948966 0 -1.5707963267948966" xyz="0 0 0"/>
    <parent link="camera_link"/>
    <child link="camera_frame"/>
  </joint>
</robot>
