<?xml version="1.0"?>
<robot name="isaac_bot"
  xmlns:xacro="http://ros.org/wiki/xacro">

  <!-- Define arguments -->
  <xacro:arg name="prefix" default=""/>
  <!-- <xacro:property name="pi" value="3.1415926535897931" /> -->

  <!-- Define robot constants -->
v

  <xacro:property name="knuckle_radius" value="0.02"/>
  <xacro:property name="knuckle_width" value="0.03"/>
  <xacro:property name="knuckle_ygap" value="0.01"/> <!-- Gap between knuckle and base_link -->

  <xacro:property name="wheel_radius" value="0.10"/>
  <xacro:property name="wheel_width" value="0.04"/>
  <xacro:property name="wheel_ygap" value="0.039"/> <!-- Gap between knuckle and wheel --> 
  <xacro:property name="wheel_zoff" value="0.05"/>
  <xacro:property name="wheel_xoff" value="0.12"/>

  <!-- Define some commonly used intertial properties  -->
  <xacro:macro name="box_inertia" params="m w h d">
    <inertial>
      <origin xyz="0 0 0" rpy="${pi/2} 0 ${pi/2}"/>
      <mass value="${m}"/>
      <inertia ixx="${(m/12) * (h*h + d*d)}" ixy="0.0" ixz="0.0" iyy="${(m/12) * (w*w + d*d)}" iyz="0.0" izz="${(m/12) * (w*w + h*h)}"/>
    </inertial>
  </xacro:macro>

  <xacro:macro name="cylinder_inertia" params="m r h">
    <inertial>
      <origin xyz="0 0 0" rpy="${pi/2} 0 0" />
      <mass value="${m}"/>
      <inertia ixx="${(m/12) * (3*r*r + h*h)}" ixy = "0" ixz = "0" iyy="${(m/12) * (3*r*r + h*h)}" iyz = "0" izz="${(m/2) * (r*r)}"/>
    </inertial>
  </xacro:macro>

  <xacro:macro name="sphere_inertia" params="m r">
    <inertial>
      <mass value="${m}"/>
      <inertia ixx="${(2/5) * m * (r*r)}" ixy="0.0" ixz="0.0" iyy="${(2/5) * m * (r*r)}" iyz="0.0" izz="${(2/5) * m * (r*r)}"/>
    </inertial>
  </xacro:macro>

  <!-- Robot Base -->
  <link name="base_link">
    <visual>
      <geometry>
        <box size="${base_length} ${base_width} ${base_height}"/>
      </geometry>
      <material name="Cyan">
        <color rgba="0 1.0 1.0 1.0"/>
      </material>
    </visual>

    <collision>
      <geometry>
        <box size="${base_length} ${base_width} ${base_height}"/>
      </geometry>
    </collision>

    <xacro:box_inertia m="15" w="${base_width}" d="${base_length}" h="${base_height}"/>
  </link>

  <!-- Robot Footprint -->
  <link name="base_footprint">
    <xacro:box_inertia m="0" w="0" d="0" h="0"/>
  </link>

  <joint name="base_joint" type="fixed">
    <parent link="base_link"/>
    <child link="base_footprint"/>
    <origin xyz="0.0 0.0 ${-(wheel_radius+wheel_zoff)}" rpy="0 0 0"/>
  </joint>

  <!-- Knuckle Link -->
  <xacro:macro name="knuckle" params="prefix y_reflect">
    <link name="${prefix}_link">
      <visual>
        <origin xyz="0 ${y_reflect*(knuckle_width/2)} 0" rpy="${pi/2} 0 0"/>
        <geometry>
          <cylinder radius="${knuckle_radius}" length="${knuckle_width}"/>
        </geometry>
        <material name="Gray">
          <color rgba="0.5 0.5 0.5 1.0"/>
        </material>
      </visual>

      <collision>
        <origin xyz="0 0 0" rpy="${pi/2} 0 0"/>
        <geometry>
          <cylinder radius="${knuckle_radius}" length="${knuckle_width}"/>
        </geometry>
      </collision>

      <xacro:cylinder_inertia m="0.5" r="${knuckle_radius}" h="${knuckle_width}"/>
    </link>

    <joint name="${prefix}_joint" type="revolute">
      <parent link="base_link"/>
      <child link="${prefix}_link"/>
      <origin xyz="${wheel_xoff} ${y_reflect*(base_width/2+knuckle_ygap)} ${-wheel_zoff}" rpy="0 0 0"/>
      <axis xyz="0 0 1"/>
      <limit lower="-0.5" upper="0.5" effort="10.0" velocity="1.0"/>
    </joint>
  </xacro:macro>

  <xacro:knuckle prefix="knuckle_left" y_reflect="1"/>
  <xacro:knuckle prefix="knuckle_right" y_reflect="-1"/>


  <!-- Wheels -->
  <xacro:macro name="wheel" params="prefix x_reflect y_reflect knuckle_exist z_off parent_link">
    <link name="${prefix}_link">
      <visual>
        <origin xyz="0 0 0" rpy="${pi/2} 0 0"/>
        <geometry>
          <cylinder radius="${wheel_radius}" length="${wheel_width}"/>
        </geometry>
        <material name="Gray">
          <color rgba="0.5 0.5 0.5 1.0"/>
        </material>
      </visual>

      <collision>
        <origin xyz="0 0 0" rpy="${pi/2} 0 0"/>
        <geometry>
          <cylinder radius="${wheel_radius}" length="${wheel_width}"/>
        </geometry>
      </collision>

      <xacro:cylinder_inertia m="0.5" r="${wheel_radius}" h="${wheel_width}"/>
    </link>

    <joint name="${prefix}_joint" type="continuous">
      <parent link="${parent_link}"/>
      <child link="${prefix}_link"/>
      <origin xyz="${x_reflect*wheel_xoff} ${y_reflect*(base_width/2+knuckle_ygap+knuckle_width+wheel_ygap)+knuckle_exist*(knuckle_width+wheel_ygap)} ${-wheel_zoff*z_off}" rpy="0 0 0"/>
      <axis xyz="0 1 0"/>
    </joint>
  </xacro:macro>

  <xacro:wheel prefix="back_left_wheel" x_reflect="-1" y_reflect="1" knuckle_exist="0" z_off="1" parent_link="base_link"/>
  <xacro:wheel prefix="back_right_wheel" x_reflect="-1" y_reflect="-1" knuckle_exist="0" z_off="1" parent_link="base_link"/>
  <xacro:wheel prefix="front_left_wheel" x_reflect="0" y_reflect="0" knuckle_exist="1" z_off="0" parent_link="knuckle_left_link"/>
  <xacro:wheel prefix="front_right_wheel" x_reflect="0" y_reflect="0" knuckle_exist="-1" z_off="0" parent_link="knuckle_right_link"/>

  <link name="imu_link">
    <visual>
      <geometry>
        <box size="0.1 0.1 0.1"/>
      </geometry>
    </visual>

    <collision>
      <geometry>
        <box size="0.1 0.1 0.1"/>
      </geometry>
    </collision>

    <xacro:box_inertia m="0.1" w="0.1" d="0.1" h="0.1"/>
  </link>

  <joint name="imu_joint" type="fixed">
    <parent link="base_link"/>
    <child link="imu_link"/>
    <origin xyz="0 0 0.01"/>
  </joint>

  <link name="lidar_link">
    <inertial>
      <origin xyz="0 0 0" rpy="0 0 0"/>
      <mass value="0.125"/>
      <inertia ixx="0.001" ixy="0" ixz="0" iyy="0.001" iyz="0" izz="0.001" />
    </inertial>

    <collision>
      <origin xyz="0 0 0" rpy="0 0 0"/>
      <geometry>
        <cylinder radius="0.0508" length="0.055"/>
      </geometry>
    </collision>

    <visual>
      <origin xyz="0 0 0" rpy="0 0 0"/>
      <geometry>
        <cylinder radius="0.0508" length="0.055"/>
      </geometry>
    </visual>
  </link>

  <joint name="lidar_joint" type="fixed">
    <parent link="base_link"/>
    <child link="lidar_link"/>
    <origin xyz="0 0 0.17" rpy="0 0 0"/>
  </joint>

  <link name="camera_link">
    <visual>
      <origin xyz="0 0 0" rpy="0 0 0"/>
      <geometry>
        <box size="0.015 0.130 0.022"/>
      </geometry>
    </visual>

    <collision>
      <origin xyz="0 0 0" rpy="0 0 0"/>
      <geometry>
        <box size="0.015 0.130 0.022"/>
      </geometry>
    </collision>

    <inertial>
      <origin xyz="0 0 0" rpy="0 0 0"/>
      <mass value="0.035"/>
      <inertia ixx="0.001" ixy="0" ixz="0" iyy="0.001" iyz="0" izz="0.001" />
    </inertial>
  </link>

  <joint name="camera_joint" type="fixed">
    <parent link="base_link"/>
    <child link="camera_link"/>
    <origin xyz="0.215 0 0.05" rpy="0 0 0"/>
  </joint>

  <link name="camera_frame"/>

  <joint name="camera_depth_joint" type="fixed">
    <origin xyz="0 0 0" rpy="${-pi/2} 0 ${-pi/2}"/>
    <parent link="camera_link"/>
    <child link="camera_frame"/>
  </joint>
</robot>